<sdf version='1.9'>
  <model name='ur5e'>
    <joint name='world_joint' type='fixed'>
      <pose relative_to='__model__'>0 0 0 0 0 0</pose>
      <parent>world</parent>
      <child>base_link</child>
    </joint>
    <link name='base_link'>
      <pose relative_to='world_joint'>0 0 0 0 0 0</pose>
      <inertial>
        <pose>0 0 0 0 0 0</pose>
        <mass>4</mass>
        <inertia>
          <ixx>0.0044333315599999999</ixx>
          <ixy>0</ixy>
          <ixz>0</ixz>
          <iyy>0.0044333315599999999</iyy>
          <iyz>0</iyz>
          <izz>0.0071999999999999998</izz>
        </inertia>
      </inertial>
      <collision name='base_link_collision'>
        <pose>0 0 0 0 0 0</pose>
        <geometry>
          <mesh>
            <scale>1 1 1</scale>
            <uri>model://base.stl</uri>
          </mesh>
        </geometry>
      </collision>
      <visual name='base_link_visual'>
        <pose>0 0 0 0 0 0</pose>
        <geometry>
          <mesh>
            <scale>1 1 1</scale>
            <uri>model://base.dae</uri>
          </mesh>
        </geometry>
        <material>
          <diffuse>0.875 0.875 0.875 1</diffuse>
          <ambient>0.875 0.875 0.875 1</ambient>
        </material>
      </visual>
    </link>
    <joint name='shoulder_pan_joint' type='revolute'>
      <pose relative_to='base_link'>0 0 0.163 0 0 0</pose>
      <parent>base_link</parent>
      <child>shoulder_link</child>
      <axis>
        <xyz>0 0 1</xyz>
        <limit>
          <lower>-6.2831853071800001</lower>
          <upper>6.2831853071800001</upper>
          <effort>150</effort>
          <velocity>3.1400000000000001</velocity>
        </limit>
        <dynamics>
          <damping>0</damping>
          <friction>0</friction>
          <spring_reference>0</spring_reference>
          <spring_stiffness>0</spring_stiffness>
        </dynamics>
      </axis>
    </joint>
    <link name='shoulder_link'>
      <pose relative_to='shoulder_pan_joint'>0 0 0 0 0 0</pose>
      <inertial>
        <pose>0 0 0 0 0 0</pose>
        <mass>3.7000000000000002</mass>
        <inertia>
          <ixx>0.010267495893</ixx>
          <ixy>0</ixy>
          <ixz>0</ixz>
          <iyy>0.010267495893</iyy>
          <iyz>0</iyz>
          <izz>0.0066600000000000001</izz>
        </inertia>
      </inertial>
      <collision name='shoulder_link_collision'>
        <pose>0 0 0 0 0 0</pose>
        <geometry>
          <mesh>
            <scale>1 1 1</scale>
            <uri>model://shoulder.stl</uri>
          </mesh>
        </geometry>
        <surface>
          <contact>
            <ode/>
          </contact>
          <friction>
            <ode/>
          </friction>
        </surface>
      </collision>
      <visual name='shoulder_link_visual'>
        <pose>0 0 0 0 0 0</pose>
        <geometry>
          <mesh>
            <scale>1 1 1</scale>
            <uri>model://shoulder.dae</uri>
          </mesh>
        </geometry>
        <material>
          <diffuse>0.875 0.875 0.875 1</diffuse>
          <ambient>0.875 0.875 0.875 1</ambient>
        </material>
      </visual>
      <self_collide>true</self_collide>
    </link>
    <joint name='shoulder_lift_joint' type='revolute'>
      <pose relative_to='shoulder_link'>0 0.138 0 0 1.570796326794897 0</pose>
      <parent>shoulder_link</parent>
      <child>upper_arm_link</child>
      <axis>
        <xyz>0 1 0</xyz>
        <limit>
          <lower>-6.2831853071800001</lower>
          <upper>6.2831853071800001</upper>
          <effort>150</effort>
          <velocity>3.1400000000000001</velocity>
        </limit>
        <dynamics>
          <damping>0</damping>
          <friction>0</friction>
          <spring_reference>0</spring_reference>
          <spring_stiffness>0</spring_stiffness>
        </dynamics>
      </axis>
    </joint>
    <link name='upper_arm_link'>
      <pose relative_to='shoulder_lift_joint'>0 0 0 0 0 0</pose>
      <inertial>
        <pose>0 0 0.2125 0 0 0</pose>
        <mass>8.3930000000000007</mass>
        <inertia>
          <ixx>0.13388578186200001</ixx>
          <ixy>0</ixy>
          <ixz>0</ixz>
          <iyy>0.13388578186200001</iyy>
          <iyz>0</iyz>
          <izz>0.0151074</izz>
        </inertia>
      </inertial>
      <collision name='upper_arm_link_collision'>
        <pose>0 0 0 0 0 0</pose>
        <geometry>
          <mesh>
            <scale>1 1 1</scale>
            <uri>model://upperarm.stl</uri>
          </mesh>
        </geometry>
        <surface>
          <contact>
            <ode/>
          </contact>
          <friction>
            <ode/>
          </friction>
        </surface>
      </collision>
      <visual name='upper_arm_link_visual'>
        <pose>0 0 0 0 0 0</pose>
        <geometry>
          <mesh>
            <scale>1 1 1</scale>
            <uri>model://upperarm.dae</uri>
          </mesh>
        </geometry>
        <material>
          <diffuse>0.875 0.875 0.875 1</diffuse>
          <ambient>0.875 0.875 0.875 1</ambient>
        </material>
      </visual>
      <self_collide>true</self_collide>
    </link>
    <joint name='elbow_joint' type='revolute'>
      <pose relative_to='upper_arm_link'>0 -0.131 0.425 0 0 0</pose>
      <parent>upper_arm_link</parent>
      <child>forearm_link</child>
      <axis>
        <xyz>0 1 0</xyz>
        <limit>
          <lower>-3.1415926535900001</lower>
          <upper>3.1415926535900001</upper>
          <effort>150</effort>
          <velocity>3.1400000000000001</velocity>
        </limit>
        <dynamics>
          <damping>0</damping>
          <friction>0</friction>
          <spring_reference>0</spring_reference>
          <spring_stiffness>0</spring_stiffness>
        </dynamics>
      </axis>
    </joint>
    <link name='forearm_link'>
      <pose relative_to='elbow_joint'>0 0 0 0 0 0</pose>
      <inertial>
        <pose>0 0 0.196 0 0 0</pose>
        <mass>2.2749999999999999</mass>
        <inertia>
          <ixx>0.031179620861500001</ixx>
          <ixy>0</ixy>
          <ixz>0</ixz>
          <iyy>0.031179620861500001</iyy>
          <iyz>0</iyz>
          <izz>0.0040949999999999997</izz>
        </inertia>
      </inertial>
      <collision name='forearm_link_collision'>
        <pose>0 0 0 0 0 0</pose>
        <geometry>
          <mesh>
            <scale>1 1 1</scale>
            <uri>model://forearm.stl</uri>
          </mesh>
        </geometry>
        <surface>
          <contact>
            <ode/>
          </contact>
          <friction>
            <ode/>
          </friction>
        </surface>
      </collision>
      <visual name='forearm_link_visual'>
        <pose>0 0 0 0 0 0</pose>
        <geometry>
          <mesh>
            <scale>1 1 1</scale>
            <uri>model://forearm.dae</uri>
          </mesh>
        </geometry>
        <material>
          <diffuse>0.875 0.875 0.875 1</diffuse>
          <ambient>0.875 0.875 0.875 1</ambient>
        </material>
      </visual>
      <self_collide>true</self_collide>
    </link>
    <joint name='wrist_1_joint' type='revolute'>
      <pose relative_to='forearm_link'>0 0 0.392 0 1.570796326794897 0</pose>
      <parent>forearm_link</parent>
      <child>wrist_1_link</child>
      <axis>
        <xyz>0 1 0</xyz>
        <limit>
          <lower>-6.2831853071800001</lower>
          <upper>6.2831853071800001</upper>
          <effort>28</effort>
          <velocity>6.2800000000000002</velocity>
        </limit>
        <dynamics>
          <damping>0</damping>
          <friction>0</friction>
          <spring_reference>0</spring_reference>
          <spring_stiffness>0</spring_stiffness>
        </dynamics>
      </axis>
    </joint>
    <link name='wrist_1_link'>
      <pose relative_to='wrist_1_joint'>0 0 0 0 0 0</pose>
      <inertial>
        <pose>0 0.127 0 0 0 0</pose>
        <mass>1.2190000000000001</mass>
        <inertia>
          <ixx>0.0025598989760399998</ixx>
          <ixy>0</ixy>
          <ixz>0</ixz>
          <iyy>0.0025598989760399998</iyy>
          <iyz>0</iyz>
          <izz>0.0021941999999999999</izz>
        </inertia>
      </inertial>
      <collision name='wrist_1_link_collision'>
        <pose>0 0 0 0 0 0</pose>
        <geometry>
          <mesh>
            <scale>1 1 1</scale>
            <uri>model://wrist1.stl</uri>
          </mesh>
        </geometry>
        <surface>
          <contact>
            <ode/>
          </contact>
          <friction>
            <ode/>
          </friction>
        </surface>
      </collision>
      <visual name='wrist_1_link_visual'>
        <pose>0 0 0 0 0 0</pose>
        <geometry>
          <mesh>
            <scale>1 1 1</scale>
            <uri>model://wrist1.dae</uri>
          </mesh>
        </geometry>
        <material>
          <diffuse>0.875 0.875 0.875 1</diffuse>
          <ambient>0.875 0.875 0.875 1</ambient>
        </material>
      </visual>
      <self_collide>true</self_collide>
    </link>
    <joint name='wrist_2_joint' type='revolute'>
      <pose relative_to='wrist_1_link'>0 0.127 0 0 0 0</pose>
      <parent>wrist_1_link</parent>
      <child>wrist_2_link</child>
      <axis>
        <xyz>0 0 1</xyz>
        <limit>
          <lower>-6.2831853071800001</lower>
          <upper>6.2831853071800001</upper>
          <effort>28</effort>
          <velocity>6.2800000000000002</velocity>
        </limit>
        <dynamics>
          <damping>0</damping>
          <friction>0</friction>
          <spring_reference>0</spring_reference>
          <spring_stiffness>0</spring_stiffness>
        </dynamics>
      </axis>
    </joint>
    <link name='wrist_2_link'>
      <pose relative_to='wrist_2_joint'>0 0 0 0 0 0</pose>
      <inertial>
        <pose>0 0 0.1 0 0 0</pose>
        <mass>1.2190000000000001</mass>
        <inertia>
          <ixx>0.0025598989760399998</ixx>
          <ixy>0</ixy>
          <ixz>0</ixz>
          <iyy>0.0025598989760399998</iyy>
          <iyz>0</iyz>
          <izz>0.0021941999999999999</izz>
        </inertia>
      </inertial>
      <collision name='wrist_2_link_collision'>
        <pose>0 0 0 0 0 0</pose>
        <geometry>
          <mesh>
            <scale>1 1 1</scale>
            <uri>model://wrist2.stl</uri>
          </mesh>
        </geometry>
        <surface>
          <contact>
            <ode/>
          </contact>
          <friction>
            <ode/>
          </friction>
        </surface>
      </collision>
      <visual name='wrist_2_link_visual'>
        <pose>0 0 0 0 0 0</pose>
        <geometry>
          <mesh>
            <scale>1 1 1</scale>
            <uri>model://wrist2.dae</uri>
          </mesh>
        </geometry>
        <material>
          <diffuse>0.875 0.875 0.875 1</diffuse>
          <ambient>0.875 0.875 0.875 1</ambient>
        </material>
      </visual>
      <self_collide>true</self_collide>
    </link>
    <joint name='wrist_3_joint' type='revolute'>
      <pose relative_to='wrist_2_link'>0 0 0.1 0 0 0</pose>
      <parent>wrist_2_link</parent>
      <child>wrist_3_link</child>
      <axis>
        <xyz>0 1 0</xyz>
        <limit>
          <lower>-6.2831853071800001</lower>
          <upper>6.2831853071800001</upper>
          <effort>28</effort>
          <velocity>6.2800000000000002</velocity>
        </limit>
        <dynamics>
          <damping>0</damping>
          <friction>0</friction>
          <spring_reference>0</spring_reference>
          <spring_stiffness>0</spring_stiffness>
        </dynamics>
      </axis>
    </joint>
    <link name='wrist_3_link'>
      <pose relative_to='wrist_3_joint'>0 0 0 0 0 0</pose>
      <inertial>
        <pose>0 0.08855000000018876 -0.03855 1.57079632679 0 0</pose>
        <mass>0.37580000000000002</mass>
        <inertia>
          <ixx>0.00080555384004502495</ixx>
          <ixy>0</ixy>
          <ixz>0</ixz>
          <iyy>0.00028028960752494992</iyy>
          <iyz>-0.00016587718050506601</iyz>
          <izz>0.00078949860752007561</izz>
        </inertia>
      </inertial>
      <collision name='wrist_3_link_collision'>
        <pose>0 0 0 0 0 0</pose>
        <geometry>
          <mesh>
            <scale>1 1 1</scale>
            <uri>model://wrist3.stl</uri>
          </mesh>
        </geometry>
        <surface>
          <contact>
            <ode/>
          </contact>
          <friction>
            <ode/>
          </friction>
        </surface>
      </collision>
      <visual name='wrist_3_link_visual'>
        <pose>0 0 0 0 0 0</pose>
        <geometry>
          <mesh>
            <scale>1 1 1</scale>
            <uri>model://wrist3.dae</uri>
          </mesh>
        </geometry>
        <material>
          <diffuse>0.875 0.875 0.875 1</diffuse>
          <ambient>0.875 0.875 0.875 1</ambient>
        </material>
      </visual>
      <self_collide>true</self_collide>
    </link>
    <plugin name='gz_ros2_control' filename='libgz_ros2_control.so'>
      <robotNamespace>/ur5e_robot</robotNamespace>
    </plugin>
    <frame name='base_link-base_fixed_joint' attached_to='base_link'>
      <pose>0 0 0 0 0 3.14159</pose>
    </frame>
    <frame name='base' attached_to='base_link-base_fixed_joint'/>
    <frame name='wrist_3_link-tool0_fixed_joint' attached_to='wrist_3_link'>
      <pose>0 0.1 0 -1.5708 0 0</pose>
    </frame>
    <frame name='tool0' attached_to='wrist_3_link-tool0_fixed_joint'/>
  </model>
</sdf>
